<?xml version="1.0" ?>
<!-- =================================================================================== -->
<!-- |    This document was autogenerated by xacro from /home/ros2/ws_RAMS/install/workcell_description/share/workcell_description/urdf/workcell.urdf.xacro | -->
<!-- |    EDITING THIS FILE BY HAND IS NOT RECOMMENDED                                 | -->
<!-- =================================================================================== -->
<robot name="workcell">
  <!-- === link list === -->
  <link name="base_link">
    <inertial>
      <mass value="100.0"/>
      <origin xyz="0 0 0.2"/>
      <inertia ixx="1.0" ixy="0" ixz="0" iyy="1.0" iyz="0" izz="1.0"/>
    </inertial>
    <visual>
      <origin rpy="0 0 0" xyz="0 0 0"/>
      <geometry>
        <mesh filename="package://workcell_description/meshes/robots/visual/base_link.stl" scale="1 1 1"/>
      </geometry>
    </visual>
    <collision>
      <origin rpy="0 0 0" xyz="0 0 0"/>
      <geometry>
        <mesh filename="package://workcell_description/meshes/robots/collision/base_link.stl" scale="1 1 1"/>
      </geometry>
    </collision>
  </link>
  <link name="link_1">
    <inertial>
      <mass value="30.0"/>
      <origin xyz="0 0 0.1"/>
      <inertia ixx="0.5" ixy="0" ixz="0" iyy="0.5" iyz="0" izz="0.5"/>
    </inertial>
    <visual>
      <origin rpy="0 0 0" xyz="0 0 0"/>
      <geometry>
        <mesh filename="package://workcell_description/meshes/robots/visual/link_1.stl" scale="1 1 1"/>
      </geometry>
    </visual>
    <collision>
      <origin rpy="0 0 0" xyz="0 0 0"/>
      <geometry>
        <mesh filename="package://workcell_description/meshes/robots/collision/link_1.stl" scale="1 1 1"/>
      </geometry>
    </collision>
  </link>
  <link name="link_2">
    <inertial>
      <mass value="35.0"/>
      <origin xyz="0 0 0.1"/>
      <inertia ixx="0.6" ixy="0" ixz="0" iyy="0.6" iyz="0" izz="0.6"/>
    </inertial>
    <visual>
      <origin rpy="0 0 0" xyz="0 0 0"/>
      <geometry>
        <mesh filename="package://workcell_description/meshes/robots/visual/link_2.stl" scale="1 1 1"/>
      </geometry>
    </visual>
    <collision>
      <origin rpy="0 0 0" xyz="0 0 0"/>
      <geometry>
        <mesh filename="package://workcell_description/meshes/robots/collision/link_2.stl" scale="1 1 1"/>
      </geometry>
    </collision>
  </link>
  <link name="link_3">
    <inertial>
      <mass value="25.0"/>
      <origin xyz="0 0 0.1"/>
      <inertia ixx="0.4" ixy="0" ixz="0" iyy="0.4" iyz="0" izz="0.4"/>
    </inertial>
    <visual>
      <origin rpy="0 0 0" xyz="0 0 0"/>
      <geometry>
        <mesh filename="package://workcell_description/meshes/robots/visual/link_3.stl" scale="1 1 1"/>
      </geometry>
    </visual>
    <collision>
      <origin rpy="0 0 0" xyz="0 0 0"/>
      <geometry>
        <mesh filename="package://workcell_description/meshes/robots/collision/link_3.stl" scale="1 1 1"/>
      </geometry>
    </collision>
  </link>
  <link name="link_4">
    <inertial>
      <mass value="20.0"/>
      <origin xyz="0 0 0.1"/>
      <inertia ixx="0.3" ixy="0" ixz="0" iyy="0.3" iyz="0" izz="0.3"/>
    </inertial>
    <visual>
      <origin rpy="0 0 0" xyz="0 0 0"/>
      <geometry>
        <mesh filename="package://workcell_description/meshes/robots/visual/link_4.stl" scale="1 1 1"/>
      </geometry>
    </visual>
    <collision>
      <origin rpy="0 0 0" xyz="0 0 0"/>
      <geometry>
        <mesh filename="package://workcell_description/meshes/robots/collision/link_4.stl" scale="1 1 1"/>
      </geometry>
    </collision>
  </link>
  <link name="link_5">
    <inertial>
      <mass value="15.0"/>
      <origin xyz="0 0 0.1"/>
      <inertia ixx="0.2" ixy="0" ixz="0" iyy="0.2" iyz="0" izz="0.2"/>
    </inertial>
    <visual>
      <origin rpy="0 0 0" xyz="0 0 0"/>
      <geometry>
        <mesh filename="package://workcell_description/meshes/robots/visual/link_5.stl" scale="1 1 1"/>
      </geometry>
    </visual>
    <collision>
      <origin rpy="0 0 0" xyz="0 0 0"/>
      <geometry>
        <mesh filename="package://workcell_description/meshes/robots/collision/link_5.stl" scale="1 1 1"/>
      </geometry>
    </collision>
  </link>
  <link name="link_6">
    <inertial>
      <mass value="10.0"/>
      <origin xyz="0 0 0.1"/>
      <inertia ixx="0.1" ixy="0" ixz="0" iyy="0.1" iyz="0" izz="0.1"/>
    </inertial>
    <visual>
      <origin rpy="0 0 0" xyz="0 0 0"/>
      <geometry>
        <mesh filename="package://workcell_description/meshes/robots/visual/link_6.stl" scale="1 1 1"/>
      </geometry>
    </visual>
    <collision>
      <origin rpy="0 0 0" xyz="0 0 0"/>
      <geometry>
        <mesh filename="package://workcell_description/meshes/robots/collision/link_6.stl" scale="1 1 1"/>
      </geometry>
    </collision>
  </link>
  <link name="cylinder">
    <inertial>
      <mass value="5.0"/>
      <origin xyz="0 0 0.1"/>
      <inertia ixx="0.05" ixy="0" ixz="0" iyy="0.05" iyz="0" izz="0.05"/>
    </inertial>
    <visual>
      <origin rpy="0 0 0" xyz="0 0 0"/>
      <geometry>
        <mesh filename="package://workcell_description/meshes/robots/visual/cylinder.stl" scale="1 1 1"/>
      </geometry>
    </visual>
    <collision>
      <origin rpy="0 0 0" xyz="0 0 0"/>
      <geometry>
        <mesh filename="package://workcell_description/meshes/robots/collision/cylinder.stl" scale="1 1 1"/>
      </geometry>
    </collision>
  </link>
  <link name="piston">
    <inertial>
      <mass value="3.0"/>
      <origin xyz="0 0 0.1"/>
      <inertia ixx="0.03" ixy="0" ixz="0" iyy="0.03" iyz="0" izz="0.03"/>
    </inertial>
    <visual>
      <origin rpy="0 0 0" xyz="0 0 0"/>
      <geometry>
        <mesh filename="package://workcell_description/meshes/robots/visual/piston.stl" scale="1 1 1"/>
      </geometry>
    </visual>
    <collision>
      <origin rpy="0 0 0" xyz="0 0 0"/>
      <geometry>
        <mesh filename="package://workcell_description/meshes/robots/collision/piston.stl" scale="1 1 1"/>
      </geometry>
    </collision>
  </link>
  <!-- === joint list === -->
  <joint name="joint_1" type="revolute">
    <origin rpy="0 0 0" xyz="0 0 0.78"/>
    <parent link="base_link"/>
    <child link="link_1"/>
    <axis xyz="0 0 1"/>
    <limit effort="1000" lower="-2.967" upper="2.967" velocity="1.919"/>
    <dynamics damping="10.0" friction="1.0"/>
  </joint>
  <joint name="joint_2" type="revolute">
    <origin rpy="0 0 0" xyz="0.32 0 0"/>
    <parent link="link_1"/>
    <child link="link_2"/>
    <axis xyz="0 1 0"/>
    <limit effort="1000" lower="-1.134" upper="1.483" velocity="1.919"/>
    <dynamics damping="10.0" friction="1.0"/>
  </joint>
  <joint name="joint_3" type="revolute">
    <origin rpy="0 0 0" xyz="0 0 1.125"/>
    <parent link="link_2"/>
    <child link="link_3"/>
    <axis xyz="0 1 0"/>
    <limit effort="1000" lower="-3.142" upper="1.221" velocity="1.919"/>
    <dynamics damping="10.0" friction="1.0"/>
  </joint>
  <joint name="joint_4" type="revolute">
    <origin rpy="0 0 0" xyz="0 0 0.2"/>
    <parent link="link_3"/>
    <child link="link_4"/>
    <axis xyz="1 0 0"/>
    <limit effort="1000" lower="-5.235" upper="5.235" velocity="3.316"/>
    <dynamics damping="10.0" friction="1.0"/>
  </joint>
  <joint name="joint_5" type="revolute">
    <origin rpy="0 0 0" xyz="1.1425 0 0"/>
    <parent link="link_4"/>
    <child link="link_5"/>
    <axis xyz="0 1 0"/>
    <limit effort="1000" lower="-2.268" upper="2.268" velocity="2.618"/>
    <dynamics damping="10.0" friction="1.0"/>
  </joint>
  <joint name="joint_6" type="revolute">
    <origin rpy="0 0 0" xyz="0.2 0 0"/>
    <parent link="link_5"/>
    <child link="link_6"/>
    <axis xyz="1 0 0"/>
    <limit effort="1000" lower="-6.283" upper="6.283" velocity="3.665"/>
    <dynamics damping="10.0" friction="1.0"/>
  </joint>
  <joint name="cylinder_joint" type="revolute">
    <origin rpy="0 0 0" xyz="-0.349 -0.194 -0.142"/>
    <parent link="link_1"/>
    <child link="cylinder"/>
    <axis xyz="0 1 0"/>
    <mimic joint="joint_2" multiplier="-0.25"/>
    <limit effort="100" lower="-0.284" upper="0.371" velocity="1.0"/>
  </joint>
  <!-- Virtual prismatic joint to provide displacement equivalent to joint_2 rotation -->
  <link name="joint_2_slider"/>
  <joint name="joint_2_slider_joint" type="prismatic">
    <origin rpy="0 0 0" xyz="0 0 0"/>
    <parent link="link_1"/>
    <child link="joint_2_slider"/>
    <axis xyz="0 1 0"/>
    <mimic joint="joint_2" multiplier="-0.1686" offset="0.0"/>
    <limit effort="100" lower="-0.25" upper="0.25" velocity="1.0"/>
  </joint>
  <joint name="piston_joint" type="prismatic">
    <origin rpy="0.20897 0 -1.5708" xyz="0 0 0"/>
    <parent link="cylinder"/>
    <child link="piston"/>
    <axis xyz="0 1 0"/>
    <mimic joint="joint_2_slider_joint" multiplier="1.0"/>
    <limit effort="100" lower="-0.25" upper="0.25" velocity="1.0"/>
  </joint>
  <link name="base"/>
  <joint name="base_link-base" type="fixed">
    <origin rpy="0 0 0" xyz="0 0 0"/>
    <parent link="base"/>
    <child link="base_link"/>
  </joint>
  <link name="flange"/>
  <joint name="joint_6-flange" type="fixed">
    <origin rpy="0 0 0" xyz="0 0 0"/>
    <parent link="link_6"/>
    <child link="flange"/>
  </joint>
  <link name="tool0"/>
  <joint name="link_6-tool0" type="fixed">
    <origin rpy="0 1.5708 0" xyz="0 0 0"/>
    <parent link="flange"/>
    <child link="tool0"/>
  </joint>
  <!--<xacro:mount_spindle
      prefix="${prefix}"
      parent_link="tool0"
      mount_xyz="0 0 0" mount_rpy="1.5708 3.1416 -1.5708"
      scale_v="${mesh_scale_visual}" scale_c="${mesh_scale_collision}"
      tcp_offset="0.150"/>-->
</robot>